
ERROR_TIME: 2021-07-26 18:25:57,231
FILE_NAME: teki_main_app.py
MODULE: teki_main_app
                        
LINE_NO: 895
ERROR_SCOPE  'if __name__ == __main__': is due to '[Errno 2] No such file or directory: 'app_resources/app_dev/french_documents.txt')'
Traceback (most recent call last):
  File "C:\Users\chris\Desktop\Bachleorarbeit\teki_main_app.py", line 891, in <module>
    run_program(default_doc, default_train)
  File "C:\Users\chris\Desktop\Bachleorarbeit\teki_main_app.py", line 778, in run_program
    doc = get_text(default_doc)
  File "C:\Users\chris\Desktop\Bachleorarbeit\teki_main_app.py", line 235, in get_text
    with open(document, mode="r", encoding="utf-8") as file:
FileNotFoundError: [Errno 2] No such file or directory: 'app_resources/app_dev/french_documents.txt'

ERROR_TIME: 2021-07-26 18:27:04,967
FILE_NAME: teki_main_app.py
MODULE: teki_main_app
                        
LINE_NO: 895
ERROR_SCOPE  'if __name__ == __main__': is due to '[Errno 2] No such file or directory: 'app_resources/app_dev/french_documents.txt')'
Traceback (most recent call last):
  File "C:\Users\chris\Desktop\Bachleorarbeit\teki_main_app.py", line 887, in <module>
    run_program(default_doc, default_train)
  File "C:\Users\chris\Desktop\Bachleorarbeit\teki_main_app.py", line 778, in run_program
    doc = get_text(default_doc)
  File "C:\Users\chris\Desktop\Bachleorarbeit\teki_main_app.py", line 235, in get_text
    with open(document, mode="r", encoding="utf-8") as file:
FileNotFoundError: [Errno 2] No such file or directory: 'app_resources/app_dev/french_documents.txt'

ERROR_TIME: 2021-07-26 18:28:28,319
FILE_NAME: teki_main_app.py
MODULE: teki_main_app
                        
LINE_NO: 430
ERROR_SCOPE xml_analysis error due to: list index out of range
Traceback (most recent call last):
  File "C:\Users\chris\Desktop\Bachleorarbeit\teki_main_app.py", line 406, in xml_analysis
    start, stop = int(corpus_range_choice[0]), int(corpus_range_choice[1])
IndexError: list index out of range

ERROR_TIME: 2021-07-26 18:28:52,971
FILE_NAME: app_auxiliary_functions.py
MODULE: app_auxiliary_functions
                        
LINE_NO: 277
ERROR_SCOPE Sub menu error: 'NoneType' object is not callable
Traceback (most recent call last):
  File "C:\Users\chris\Desktop\Bachleorarbeit\app_resources\app_auxiliary_functions.py", line 274, in sub_menu
    return options_func_dict()
  File "C:\Users\chris\Desktop\Bachleorarbeit\teki_main_app.py", line 457, in txt_analysis
    tokens = text.split()
TypeError: 'NoneType' object is not callable
