
ERROR_TIME: 2021-07-26 09:16:39,285
FILE_NAME: teki_main_app.py
MODULE: teki_main_app
                        
LINE_NO: 401
ERROR_SCOPE dict contains fields not in fieldnames: 'sentence:'
Traceback (most recent call last):
  File "C:\Users\chris\Desktop\Bachleorarbeit\teki_main_app.py", line 385, in extract_xml_text
    save_sentences(collective_results,"hope.csv")
  File "C:\Users\chris\Desktop\Bachleorarbeit\app_resources\auxiliary_functions.py", line 179, in save_sentences
    writer.writerow(
  File "C:\Users\chris\AppData\Local\Programs\Python\Python39\lib\csv.py", line 154, in writerow
    return self.writer.writerow(self._dict_to_list(rowdict))
  File "C:\Users\chris\AppData\Local\Programs\Python\Python39\lib\csv.py", line 149, in _dict_to_list
    raise ValueError("dict contains fields not in fieldnames: "
ValueError: dict contains fields not in fieldnames: 'sentence:'

ERROR_TIME: 2021-07-26 09:16:45,420
FILE_NAME: teki_main_app.py
MODULE: teki_main_app
                        
LINE_NO: 401
ERROR_SCOPE invalid literal for int() with base 10: '0,9'
Traceback (most recent call last):
  File "C:\Users\chris\Desktop\Bachleorarbeit\teki_main_app.py", line 370, in extract_xml_text
    start, stop = int(corpus_range_choice[0]), int(corpus_range_choice[1])
ValueError: invalid literal for int() with base 10: '0,9'

ERROR_TIME: 2021-07-26 09:33:53,528
FILE_NAME: auxiliary_functions.py
MODULE: auxiliary_functions
                        
LINE_NO: 234
ERROR_SCOPE local variable 'print' referenced before assignment
Traceback (most recent call last):
  File "C:\Users\chris\Desktop\Bachleorarbeit\app_resources\auxiliary_functions.py", line 231, in sub_menu
    return options_func_dict()
  File "C:\Users\chris\Desktop\Bachleorarbeit\teki_main_app.py", line 329, in extract_xml_text
    print(num, corpus)
UnboundLocalError: local variable 'print' referenced before assignment

ERROR_TIME: 2021-07-26 09:34:00,276
FILE_NAME: teki_main_app.py
MODULE: teki_main_app
                        
LINE_NO: 699
ERROR_SCOPE 'function' object is not iterable
Traceback (most recent call last):
  File "C:\Users\chris\Desktop\Bachleorarbeit\teki_main_app.py", line 694, in run_program
    tagged = spacy_tagger(content)
  File "C:\Users\chris\Desktop\Bachleorarbeit\teki_main_app.py", line 470, in spacy_tagger
    for key in corpus_content:
TypeError: 'function' object is not iterable

ERROR_TIME: 2021-07-26 09:35:50,415
FILE_NAME: teki_main_app.py
MODULE: teki_main_app
                        
LINE_NO: 410
ERROR_SCOPE 'NoneType' object has no attribute 'getText'
Traceback (most recent call last):
  File "C:\Users\chris\Desktop\Bachleorarbeit\teki_main_app.py", line 402, in extract_xml_text
    corpus_text = soup.find("post", {"xml:id": xml_tag_id[i]}).getText().strip().split()
AttributeError: 'NoneType' object has no attribute 'getText'

ERROR_TIME: 2021-07-26 09:37:48,494
FILE_NAME: teki_main_app.py
MODULE: teki_main_app
                        
LINE_NO: 410
ERROR_SCOPE 'NoneType' object has no attribute 'getText'
Traceback (most recent call last):
  File "C:\Users\chris\Desktop\Bachleorarbeit\teki_main_app.py", line 402, in extract_xml_text
    corpus_text = soup.find("post", {"xml:id": xml_tag_id[i]}).getText().strip().split()
AttributeError: 'NoneType' object has no attribute 'getText'

ERROR_TIME: 2021-07-26 09:40:51,211
FILE_NAME: teki_main_app.py
MODULE: teki_main_app
                        
LINE_NO: 410
ERROR_SCOPE 'NoneType' object has no attribute 'getText'
Traceback (most recent call last):
  File "C:\Users\chris\Desktop\Bachleorarbeit\teki_main_app.py", line 402, in extract_xml_text
    corpus_text = soup.find("post", {"xml:id": xml_tag_id[i]}).getText().strip().split()
AttributeError: 'NoneType' object has no attribute 'getText'

ERROR_TIME: 2021-07-26 10:25:19,688
FILE_NAME: auxiliary_functions.py
MODULE: auxiliary_functions
                        
LINE_NO: 233
ERROR_SCOPE name 'res' is not defined
Traceback (most recent call last):
  File "C:\Users\chris\Desktop\Bachleorarbeit\app_resources\auxiliary_functions.py", line 230, in sub_menu
    return options_func_dict()
  File "C:\Users\chris\Desktop\Bachleorarbeit\teki_main_app.py", line 439, in extract_text
    print(res)
NameError: name 'res' is not defined

ERROR_TIME: 2021-07-26 10:25:25,824
FILE_NAME: teki_main_app.py
MODULE: teki_main_app
                        
LINE_NO: 701
ERROR_SCOPE 'function' object is not iterable
Traceback (most recent call last):
  File "C:\Users\chris\Desktop\Bachleorarbeit\teki_main_app.py", line 696, in run_program
    tagged = spacy_tagger(content)
  File "C:\Users\chris\Desktop\Bachleorarbeit\teki_main_app.py", line 472, in spacy_tagger
    for key in corpus_content:
TypeError: 'function' object is not iterable

ERROR_TIME: 2021-07-26 12:02:51,926
FILE_NAME: teki_main_app.py
MODULE: teki_main_app
                        
LINE_NO: 856
ERROR_SCOPE  'if __name__ == __main__': is due to 'unhashable type: 'list')'
Traceback (most recent call last):
  File "C:\Users\chris\Desktop\Bachleorarbeit\teki_main_app.py", line 847, in <module>
    run_program(default_doc, default_train)
  File "C:\Users\chris\Desktop\Bachleorarbeit\teki_main_app.py", line 799, in run_program
    probs = get_probs(freq)
  File "C:\Users\chris\Desktop\Bachleorarbeit\teki_main_app.py", line 641, in get_probs
    if freq_feat_1.get(element, 0) > 0:
TypeError: unhashable type: 'list'

ERROR_TIME: 2021-07-26 12:03:28,409
FILE_NAME: teki_main_app.py
MODULE: teki_main_app
                        
LINE_NO: 856
ERROR_SCOPE  'if __name__ == __main__': is due to 'unhashable type: 'list')'
Traceback (most recent call last):
  File "C:\Users\chris\Desktop\Bachleorarbeit\teki_main_app.py", line 847, in <module>
    run_program(default_doc, default_train)
  File "C:\Users\chris\Desktop\Bachleorarbeit\teki_main_app.py", line 799, in run_program
    probs = get_probs(freq)
  File "C:\Users\chris\Desktop\Bachleorarbeit\teki_main_app.py", line 653, in get_probs
    results[element] = oral, lit
TypeError: unhashable type: 'list'

ERROR_TIME: 2021-07-26 12:04:44,801
FILE_NAME: teki_main_app.py
MODULE: teki_main_app
                        
LINE_NO: 853
ERROR_SCOPE  'if __name__ == __main__': is due to 'local variable 'word' referenced before assignment)'
Traceback (most recent call last):
  File "C:\Users\chris\Desktop\Bachleorarbeit\teki_main_app.py", line 844, in <module>
    run_program(default_doc, default_train)
  File "C:\Users\chris\Desktop\Bachleorarbeit\teki_main_app.py", line 796, in run_program
    probs = get_probs(freq)
  File "C:\Users\chris\Desktop\Bachleorarbeit\teki_main_app.py", line 627, in get_probs
    vocabulary.add(word)
UnboundLocalError: local variable 'word' referenced before assignment

ERROR_TIME: 2021-07-26 12:10:39,063
FILE_NAME: teki_main_app.py
MODULE: teki_main_app
                        
LINE_NO: 851
ERROR_SCOPE  'if __name__ == __main__': is due to ''ORAL')'
Traceback (most recent call last):
  File "C:\Users\chris\Desktop\Bachleorarbeit\teki_main_app.py", line 842, in <module>
    run_program(default_doc, default_train)
  File "C:\Users\chris\Desktop\Bachleorarbeit\teki_main_app.py", line 797, in run_program
    classify(text.split(), probs)
  File "C:\Users\chris\Desktop\Bachleorarbeit\teki_main_app.py", line 665, in classify
    oral_prob, lit_prob = prior_prob["ORAL"], prior_prob["LIT"]
KeyError: 'ORAL'

ERROR_TIME: 2021-07-26 12:18:54,491
FILE_NAME: teki_main_app.py
MODULE: teki_main_app
                        
LINE_NO: 863
ERROR_SCOPE  'if __name__ == __main__': is due to 'name 'nN' is not defined)'
Traceback (most recent call last):
  File "C:\Users\chris\Desktop\Bachleorarbeit\teki_main_app.py", line 854, in <module>
    run_program(default_doc, default_train)
  File "C:\Users\chris\Desktop\Bachleorarbeit\teki_main_app.py", line 809, in run_program
    classify(text.split(), probs)
  File "C:\Users\chris\Desktop\Bachleorarbeit\teki_main_app.py", line 682, in classify
    literacy_smooth = lit_prob / nN
NameError: name 'nN' is not defined
